<sdf version='1.7'>
  <world name='default'>
    <light name='sun' type='directional'>
      <cast_shadows>1</cast_shadows>
      <pose>0 0 10 0 -0 0</pose>
      <diffuse>0.8 0.8 0.8 1</diffuse>
      <specular>0.2 0.2 0.2 1</specular>
      <attenuation>
        <range>1000</range>
        <constant>0.9</constant>
        <linear>0.01</linear>
        <quadratic>0.001</quadratic>
      </attenuation>
      <direction>-0.5 0.1 -0.9</direction>
      <spot>
        <inner_angle>0</inner_angle>
        <outer_angle>0</outer_angle>
        <falloff>0</falloff>
      </spot>
    </light>
    <model name='ground_plane'>
      <static>1</static>
      <link name='link'>
        <collision name='collision'>
          <geometry>
            <plane>
              <normal>0 0 1</normal>
              <size>100 100</size>
            </plane>
          </geometry>
          <surface>
            <friction>
              <ode>
                <mu>100</mu>
                <mu2>50</mu2>
              </ode>
              <torsional>
                <ode/>
              </torsional>
            </friction>
            <contact>
              <ode/>
            </contact>
            <bounce/>
          </surface>
          <max_contacts>10</max_contacts>
        </collision>
        <visual name='visual'>
          <cast_shadows>0</cast_shadows>
          <geometry>
            <plane>
              <normal>0 0 1</normal>
              <size>100 100</size>
            </plane>
          </geometry>
          <material>
            <script>
              <uri>file://media/materials/scripts/gazebo.material</uri>
              <name>Gazebo/Grey</name>
            </script>
          </material>
        </visual>
        <self_collide>0</self_collide>
        <enable_wind>0</enable_wind>
        <kinematic>0</kinematic>
      </link>
    </model>
    <gravity>0 0 -9.8</gravity>
    <magnetic_field>6e-06 2.3e-05 -4.2e-05</magnetic_field>
    <atmosphere type='adiabatic'/>
    <physics type='ode'>
      <max_step_size>0.001</max_step_size>
      <real_time_factor>1</real_time_factor>
      <real_time_update_rate>1000</real_time_update_rate>
    </physics>
    <scene>
      <ambient>0.4 0.4 0.4 1</ambient>
      <background>0.7 0.7 0.7 1</background>
      <shadows>1</shadows>
    </scene>
    <audio>
      <device>default</device>
    </audio>
    <wind/>
    <spherical_coordinates>
      <surface_model>EARTH_WGS84</surface_model>
      <latitude_deg>0</latitude_deg>
      <longitude_deg>0</longitude_deg>
      <elevation>0</elevation>
      <heading_deg>0</heading_deg>
    </spherical_coordinates>
    <model name='table_marble'>
      <static>1</static>
      <pose>-0.066967 0.013028 0.648 0 -0 0</pose>
      <link name='link'>
        <collision name='collision'>
          <geometry>
            <mesh>
              <uri>model:///table_marble/meshes/table_lightmap.dae</uri>
              <scale>0.25 0.25 0.25</scale>
            </mesh>
          </geometry>
          <max_contacts>10</max_contacts>
          <surface>
            <friction>
              <ode>
                <mu>1.5</mu>
                <mu2>1.5</mu2>
              </ode>
              <torsional>
                <ode/>
              </torsional>
            </friction>
            <contact>
              <ode>
                <soft_cfm>0.0001</soft_cfm>
                <soft_erp>0.2</soft_erp>
                <kp>1e+06</kp>
                <kd>10</kd>
              </ode>
            </contact>
            <bounce/>
            <friction>
              <torsional>
                <ode/>
              </torsional>
              <ode/>
            </friction>
          </surface>
        </collision>
        <visual name='visual'>
          <geometry>
            <mesh>
              <uri>model://table_marble/meshes/table_lightmap.dae</uri>
              <scale>0.25 0.25 0.25</scale>
            </mesh>
          </geometry>
          <material>
            <script>
              <uri>model://table_marble/materials/scripts</uri>
              <uri>model://table_marble/materials/textures</uri>
              <name>Table/Marble_Lightmap</name>
            </script>
            <lighting>0</lighting>
          </material>
        </visual>
        <self_collide>0</self_collide>
        <inertial>
          <pose>0 0 0 0 -0 0</pose>
          <inertia>
            <ixx>1</ixx>
            <ixy>0</ixy>
            <ixz>0</ixz>
            <iyy>1</iyy>
            <iyz>0</iyz>
            <izz>1</izz>
          </inertia>
          <mass>100</mass>
        </inertial>
        <enable_wind>0</enable_wind>
        <kinematic>0</kinematic>
      </link>
    </model>
    <model name='table'>
      <static>1</static>
      <link name='link'>
        <collision name='surface'>
          <pose>0 0 1 0 -0 0</pose>
          <geometry>
            <box>
              <size>1.5 0.8 0.03</size>
            </box>
          </geometry>
          <surface>
            <friction>
              <ode>
                <mu>1.5</mu>
                <mu2>1.5</mu2>
              </ode>
              <torsional>
                <ode/>
              </torsional>
            </friction>
            <contact>
              <ode>
                <soft_cfm>0.0001</soft_cfm>
                <soft_erp>0.4</soft_erp>
                <kp>1e+06</kp>
                <kd>10</kd>
              </ode>
            </contact>
            <bounce/>
          </surface>
          <max_contacts>10</max_contacts>
        </collision>
        <visual name='visual1'>
          <pose>0 0 1 0 -0 0</pose>
          <geometry>
            <box>
              <size>1.5 0.8 0.03</size>
            </box>
          </geometry>
          <material>
            <script>
              <uri>file://media/materials/scripts/gazebo.material</uri>
              <name>Gazebo/Wood</name>
            </script>
          </material>
        </visual>
        <collision name='front_left_leg'>
          <pose>0.68 0.38 0.5 0 -0 0</pose>
          <geometry>
            <cylinder>
              <radius>0.02</radius>
              <length>1</length>
            </cylinder>
          </geometry>
          <max_contacts>10</max_contacts>
          <surface>
            <contact>
              <ode/>
            </contact>
            <bounce/>
            <friction>
              <torsional>
                <ode/>
              </torsional>
              <ode/>
            </friction>
          </surface>
        </collision>
        <visual name='front_left_leg'>
          <pose>0.68 0.38 0.5 0 -0 0</pose>
          <geometry>
            <cylinder>
              <radius>0.02</radius>
              <length>1</length>
            </cylinder>
          </geometry>
          <material>
            <script>
              <uri>file://media/materials/scripts/gazebo.material</uri>
              <name>Gazebo/Grey</name>
            </script>
          </material>
        </visual>
        <collision name='front_right_leg'>
          <pose>0.68 -0.38 0.5 0 -0 0</pose>
          <geometry>
            <cylinder>
              <radius>0.02</radius>
              <length>1</length>
            </cylinder>
          </geometry>
          <max_contacts>10</max_contacts>
          <surface>
            <contact>
              <ode/>
            </contact>
            <bounce/>
            <friction>
              <torsional>
                <ode/>
              </torsional>
              <ode/>
            </friction>
          </surface>
        </collision>
        <visual name='front_right_leg'>
          <pose>0.68 -0.38 0.5 0 -0 0</pose>
          <geometry>
            <cylinder>
              <radius>0.02</radius>
              <length>1</length>
            </cylinder>
          </geometry>
          <material>
            <script>
              <uri>file://media/materials/scripts/gazebo.material</uri>
              <name>Gazebo/Grey</name>
            </script>
          </material>
        </visual>
        <collision name='back_right_leg'>
          <pose>-0.68 -0.38 0.5 0 -0 0</pose>
          <geometry>
            <cylinder>
              <radius>0.02</radius>
              <length>1</length>
            </cylinder>
          </geometry>
          <max_contacts>10</max_contacts>
          <surface>
            <contact>
              <ode/>
            </contact>
            <bounce/>
            <friction>
              <torsional>
                <ode/>
              </torsional>
              <ode/>
            </friction>
          </surface>
        </collision>
        <visual name='back_right_leg'>
          <pose>-0.68 -0.38 0.5 0 -0 0</pose>
          <geometry>
            <cylinder>
              <radius>0.02</radius>
              <length>1</length>
            </cylinder>
          </geometry>
          <material>
            <script>
              <uri>file://media/materials/scripts/gazebo.material</uri>
              <name>Gazebo/Grey</name>
            </script>
          </material>
        </visual>
        <collision name='back_left_leg'>
          <pose>-0.68 0.38 0.5 0 -0 0</pose>
          <geometry>
            <cylinder>
              <radius>0.02</radius>
              <length>1</length>
            </cylinder>
          </geometry>
          <max_contacts>10</max_contacts>
          <surface>
            <contact>
              <ode/>
            </contact>
            <bounce/>
            <friction>
              <torsional>
                <ode/>
              </torsional>
              <ode/>
            </friction>
          </surface>
        </collision>
        <visual name='back_left_leg'>
          <pose>-0.68 0.38 0.5 0 -0 0</pose>
          <geometry>
            <cylinder>
              <radius>0.02</radius>
              <length>1</length>
            </cylinder>
          </geometry>
          <material>
            <script>
              <uri>file://media/materials/scripts/gazebo.material</uri>
              <name>Gazebo/Grey</name>
            </script>
          </material>
        </visual>
        <self_collide>0</self_collide>
        <inertial>
          <pose>0 0 0 0 -0 0</pose>
          <inertia>
            <ixx>1</ixx>
            <ixy>0</ixy>
            <ixz>0</ixz>
            <iyy>1</iyy>
            <iyz>0</iyz>
            <izz>1</izz>
          </inertia>
          <mass>50</mass>
        </inertial>
        <enable_wind>0</enable_wind>
        <kinematic>0</kinematic>
      </link>
      <pose>0.056077 0.80177 0 0 -0 0</pose>
    </model>
    <state world_name='default'>
      <sim_time>496 631000000</sim_time>
      <real_time>64 365484183</real_time>
      <wall_time>1774450499 304549963</wall_time>
      <iterations>64282</iterations>
      <model name='cobot'>
        <pose>-0 -0 0.965 6.1e-05 -0 0</pose>
        <scale>1 1 1</scale>
        <link name='base_link'>
          <pose>-0 -0 0.965 6.1e-05 -0 0</pose>
          <velocity>-0 0 0 0 -0 0</velocity>
          <acceleration>-0 0 0 0 -0 0</acceleration>
          <wrench>-0 0 0 0 -0 0</wrench>
        </link>
        <link name='forearm_link'>
          <pose>0.00049 0.0001 1.7043 1.7889 1.56999 -2.92336</pose>
          <velocity>2.1e-05 0 -0 0 -2.3e-05 7.5e-05</velocity>
          <acceleration>0.007805 5.8e-05 -1e-05 0.003356 0.045552 2.30342</acceleration>
          <wrench>0.033327 0.000247 -4.5e-05 0 -0 0</wrench>
        </link>
        <link name='robotiq_85_left_finger_tip_link'>
          <pose>0.026821 0.368209 2.3923 -1.57099 -0.002913 8e-06</pose>
          <velocity>-3.8e-05 -1.1e-05 1e-05 1e-06 -0.000413 -0.000455</velocity>
          <acceleration>-0.030973 -0.004111 0.004246 0.334392 -1.44863 -0.158918</acceleration>
          <wrench>-0.001322 -0.000175 0.000181 0 -0 0</wrench>
        </link>
        <link name='robotiq_85_left_inner_knuckle_link'>
          <pose>0.013816 0.317783 2.39228 -1.57298 -0.001871 0.793599</pose>
          <velocity>3.7e-05 -2e-06 5e-06 -6e-06 -0.000413 0.001646</velocity>
          <acceleration>-0.010893 -0.00621 0.003863 -0.472809 -0.65222 1.55457</acceleration>
          <wrench>-0.000323 -0.000184 0.000115 0 -0 0</wrench>
        </link>
        <link name='robotiq_85_left_knuckle_link'>
          <pose>0.031717 0.311268 2.39233 -1.57301 -0.001893 0.793599</pose>
          <velocity>3.6e-05 -4e-06 1.3e-05 -5e-06 -0.000413 0.001308</velocity>
          <acceleration>-0.001545 0.012256 0.017644 -0.285346 -0.895872 0.748911</acceleration>
          <wrench>-8.7e-05 0.000692 0.000996 0 -0 0</wrench>
        </link>
        <link name='robotiq_85_right_finger_tip_link'>
          <pose>-0.02459 0.368208 2.39215 -1.57099 -0.002817 8e-06</pose>
          <velocity>-3.6e-05 1.1e-05 -1.1e-05 0 -0.000413 -0.00036</velocity>
          <acceleration>-0.030521 0.00553 -0.004953 -0.378384 -1.48604 -0.128258</acceleration>
          <wrench>-0.001303 0.000236 -0.000211 0 -0 0</wrench>
        </link>
        <link name='robotiq_85_right_inner_knuckle_link'>
          <pose>-0.011584 0.317783 2.3922 -1.56889 -0.002146 -0.79358</pose>
          <velocity>3.7e-05 2e-06 -5e-06 -6e-06 -0.000413 0.001655</velocity>
          <acceleration>-0.011228 0.005779 -0.00455 0.473734 -0.669129 1.58439</acceleration>
          <wrench>-0.000333 0.000172 -0.000135 0 -0 0</wrench>
        </link>
        <link name='robotiq_85_right_knuckle_link'>
          <pose>-0.029485 0.311268 2.39215 -1.56889 -0.002134 -0.79358</pose>
          <velocity>3.6e-05 5e-06 -1.3e-05 -4e-06 -0.000413 0.001279</velocity>
          <acceleration>-0.000366 -0.011714 -0.018106 0.264007 -0.937598 0.740633</acceleration>
          <wrench>-2.1e-05 -0.000661 -0.001022 0 -0 0</wrench>
        </link>
        <link name='shoulder_link'>
          <pose>0 -7e-06 1.0923 0.000134 8e-06 -3.14146</pose>
          <velocity>-0 0 -0 0 -0 7.5e-05</velocity>
          <acceleration>-0.002021 -0.001572 0 0.000163 -0.000585 0.074865</acceleration>
          <wrench>-0.01435 -0.011164 1e-06 0 -0 0</wrench>
        </link>
        <link name='upper_arm_link'>
          <pose>0 -7e-06 1.0923 1.78383 1.56998 -2.92843</pose>
          <velocity>-0 0 -0 0 3.4e-05 7.5e-05</velocity>
          <acceleration>-0.003982 1.4e-05 -6e-06 -6e-05 -0.007382 2.05129</acceleration>
          <wrench>-0.05057 0.000172 -8.1e-05 0 -0 0</wrench>
        </link>
        <link name='wrist_1_link'>
          <pose>0.000918 0.164142 2.27657 -1.57096 0.001725 0.000132</pose>
          <velocity>-5e-06 0 -0 0 0.000173 7.5e-05</velocity>
          <acceleration>-0.002421 7.3e-05 -1.2e-05 0.000513 0.220232 0.100977</acceleration>
          <wrench>-0.004842 0.000146 -2.3e-05 0 -0 0</wrench>
        </link>
        <link name='wrist_2_link'>
          <pose>0.001117 0.164163 2.39227 -0.000185 0.001725 7e-06</pose>
          <velocity>1.5e-05 0 -0 0 0.000173 -0.000145</velocity>
          <acceleration>0.016411 8.7e-05 -4.6e-05 -0.000489 0.173092 -0.144777</acceleration>
          <wrench>0.032822 0.000174 -9.2e-05 0 -0 0</wrench>
        </link>
        <link name='wrist_3_link'>
          <pose>0.001116 0.256363 2.39225 -1.57099 -0.002865 8e-06</pose>
          <velocity>2.8e-05 0 -0 0 -0.000413 -0.000145</velocity>
          <acceleration>0.025043 9.6e-05 -9e-05 -0.000675 -0.587927 0.067207</acceleration>
          <wrench>0.031251 0.000119 -0.000112 0 -0 0</wrench>
        </link>
      </model>
      <model name='coca_cola'>
        <pose>0.311937 -0.996188 0.908104 0.001116 -0.004148 -2.5e-05</pose>
        <scale>1 1 1</scale>
        <link name='link'>
          <pose>0.31146 -0.996316 1.0231 0.001116 -0.004148 -2.5e-05</pose>
          <velocity>0 0 0 0 -0 0</velocity>
          <acceleration>-1e-06 -0 1.3e-05 3e-06 -1.3e-05 -0</acceleration>
          <wrench>-0 -0 5e-06 0 -0 0</wrench>
        </link>
      </model>
      <model name='ground_plane'>
        <pose>0 0 0 0 -0 0</pose>
        <scale>1 1 1</scale>
        <link name='link'>
          <pose>0 0 0 0 -0 0</pose>
          <velocity>0 0 0 0 -0 0</velocity>
          <acceleration>0 0 0 0 -0 0</acceleration>
          <wrench>0 0 0 0 -0 0</wrench>
        </link>
      </model>
      <model name='table'>
        <pose>0.056083 0.801191 -1.2e-05 0 -0 2.5e-05</pose>
        <scale>1 1 1</scale>
        <link name='link'>
          <pose>0.056083 0.801191 -1.2e-05 0 -0 2.5e-05</pose>
          <velocity>0 0 0 0 -0 0</velocity>
          <acceleration>0 0 0 0 -0 0</acceleration>
          <wrench>0 0 0 0 -0 0</wrench>
        </link>
      </model>
      <model name='table_marble'>
        <pose>-0.071006 -1.06851 0.644348 -0.004143 -0.001114 1.57104</pose>
        <scale>1 1 1</scale>
        <link name='link'>
          <pose>-0.071006 -1.06851 0.644348 -0.004143 -0.001114 1.57104</pose>
          <velocity>0 0 0 0 -0 0</velocity>
          <acceleration>0 0 0 0 -0 0</acceleration>
          <wrench>0 0 0 0 -0 0</wrench>
        </link>
      </model>
      <light name='sun'>
        <pose>0 0 10 0 -0 0</pose>
      </light>
    </state>
    <gui fullscreen='0'>
      <camera name='user_camera'>
        <pose>0.987077 -2.05355 1.82414 -0 0.408 2.044</pose>
        <view_controller>orbit</view_controller>
        <projection_type>perspective</projection_type>
      </camera>
    </gui>
    <plugin name='gazebo_link_attacher' filename='libgazebo_link_attacher.so'/>
    <model name='cobot'>
      <joint name='base_joint' type='fixed'>
        <pose relative_to='__model__'>0 0 0 0 -0 0</pose>
        <parent>world</parent>
        <child>base_link</child>
      </joint>
      <link name='base_link'>
        <pose relative_to='base_joint'>0 0 0 0 -0 0</pose>
        <inertial>
          <pose>0 0 0 0 -0 0</pose>
          <mass>4</mass>
          <inertia>
            <ixx>0.00610633</ixx>
            <ixy>0</ixy>
            <ixz>0</ixz>
            <iyy>0.00610633</iyy>
            <iyz>0</iyz>
            <izz>0.01125</izz>
          </inertia>
        </inertial>
        <collision name='base_link_inertia_collision'>
          <pose>0 0 0 0 -0 0</pose>
          <geometry>
            <mesh>
              <scale>1 1 1</scale>
              <uri>file:///home/farhan/ros2_ws/install/ur_description/share/ur_description/meshes/ur10/collision/base.stl</uri>
            </mesh>
          </geometry>
          <max_contacts>10</max_contacts>
          <surface>
            <contact>
              <ode/>
            </contact>
            <bounce/>
            <friction>
              <torsional>
                <ode/>
              </torsional>
              <ode/>
            </friction>
          </surface>
        </collision>
        <visual name='base_link_inertia_visual'>
          <pose>0 0 0 0 -0 0</pose>
          <geometry>
            <mesh>
              <scale>1 1 1</scale>
              <uri>file:///home/farhan/ros2_ws/install/ur_description/share/ur_description/meshes/ur10/visual/base.dae</uri>
            </mesh>
          </geometry>
        </visual>
        <self_collide>0</self_collide>
        <enable_wind>0</enable_wind>
        <kinematic>0</kinematic>
      </link>
      <joint name='shoulder_pan_joint' type='revolute'>
        <pose relative_to='base_link'>0 0 0.1273 0 -0 3.14159</pose>
        <parent>base_link</parent>
        <child>shoulder_link</child>
        <axis>
          <xyz>0 0 1</xyz>
          <limit>
            <lower>-6.28319</lower>
            <upper>6.28319</upper>
            <effort>330</effort>
            <velocity>2.0944</velocity>
          </limit>
          <dynamics>
            <damping>0</damping>
            <friction>0</friction>
            <spring_reference>0</spring_reference>
            <spring_stiffness>0</spring_stiffness>
          </dynamics>
        </axis>
      </joint>
      <link name='shoulder_link'>
        <pose relative_to='shoulder_pan_joint'>0 0 0 0 -0 0</pose>
        <inertial>
          <pose>0.021 -0.027 0 1.5708 -0 0</pose>
          <mass>7.1</mass>
          <inertia>
            <ixx>0.03408</ixx>
            <ixy>2e-05</ixy>
            <ixz>-0.00425</ixz>
            <iyy>0.03529</iyy>
            <iyz>8e-05</iyz>
            <izz>0.02156</izz>
          </inertia>
        </inertial>
        <collision name='shoulder_link_collision'>
          <pose>0 0 0 0 -0 3.14159</pose>
          <geometry>
            <mesh>
              <scale>1 1 1</scale>
              <uri>file:///home/farhan/ros2_ws/install/ur_description/share/ur_description/meshes/ur10/collision/shoulder.stl</uri>
            </mesh>
          </geometry>
          <max_contacts>10</max_contacts>
          <surface>
            <contact>
              <ode/>
            </contact>
            <bounce/>
            <friction>
              <torsional>
                <ode/>
              </torsional>
              <ode/>
            </friction>
          </surface>
        </collision>
        <visual name='shoulder_link_visual'>
          <pose>0 0 0 0 -0 3.14159</pose>
          <geometry>
            <mesh>
              <scale>1 1 1</scale>
              <uri>file:///home/farhan/ros2_ws/install/ur_description/share/ur_description/meshes/ur10/visual/shoulder.dae</uri>
            </mesh>
          </geometry>
        </visual>
        <self_collide>0</self_collide>
        <enable_wind>0</enable_wind>
        <kinematic>0</kinematic>
      </link>
      <joint name='shoulder_lift_joint' type='revolute'>
        <pose relative_to='shoulder_link'>0 0 0 1.5708 -0 0</pose>
        <parent>shoulder_link</parent>
        <child>upper_arm_link</child>
        <axis>
          <xyz>0 0 1</xyz>
          <limit>
            <lower>-6.28319</lower>
            <upper>6.28319</upper>
            <effort>330</effort>
            <velocity>2.0944</velocity>
          </limit>
          <dynamics>
            <damping>0</damping>
            <friction>0</friction>
            <spring_reference>0</spring_reference>
            <spring_stiffness>0</spring_stiffness>
          </dynamics>
        </axis>
      </joint>
      <link name='upper_arm_link'>
        <pose relative_to='shoulder_lift_joint'>0 0 0 0 -0 0</pose>
        <inertial>
          <pose>-0.232 0 0.158 0 -0 0</pose>
          <mass>12.7</mass>
          <inertia>
            <ixx>0.02814</ixx>
            <ixy>5e-05</ixy>
            <ixz>-0.01561</ixz>
            <iyy>0.77068</iyy>
            <iyz>2e-05</iyz>
            <izz>0.76943</izz>
          </inertia>
        </inertial>
        <collision name='upper_arm_link_collision'>
          <pose>0 0 0.220941 1.5708 0 -1.5708</pose>
          <geometry>
            <mesh>
              <scale>1 1 1</scale>
              <uri>file:///home/farhan/ros2_ws/install/ur_description/share/ur_description/meshes/ur10/collision/upperarm.stl</uri>
            </mesh>
          </geometry>
          <max_contacts>10</max_contacts>
          <surface>
            <contact>
              <ode/>
            </contact>
            <bounce/>
            <friction>
              <torsional>
                <ode/>
              </torsional>
              <ode/>
            </friction>
          </surface>
        </collision>
        <visual name='upper_arm_link_visual'>
          <pose>0 0 0.220941 1.5708 0 -1.5708</pose>
          <geometry>
            <mesh>
              <scale>1 1 1</scale>
              <uri>file:///home/farhan/ros2_ws/install/ur_description/share/ur_description/meshes/ur10/visual/upperarm.dae</uri>
            </mesh>
          </geometry>
        </visual>
        <self_collide>0</self_collide>
        <enable_wind>0</enable_wind>
        <kinematic>0</kinematic>
      </link>
      <joint name='elbow_joint' type='revolute'>
        <pose relative_to='upper_arm_link'>-0.612 0 0 0 -0 0</pose>
        <parent>upper_arm_link</parent>
        <child>forearm_link</child>
        <axis>
          <xyz>0 0 1</xyz>
          <limit>
            <lower>-3.14159</lower>
            <upper>3.14159</upper>
            <effort>150</effort>
            <velocity>3.14159</velocity>
          </limit>
          <dynamics>
            <damping>0</damping>
            <friction>0</friction>
            <spring_reference>0</spring_reference>
            <spring_stiffness>0</spring_stiffness>
          </dynamics>
        </axis>
      </joint>
      <link name='forearm_link'>
        <pose relative_to='elbow_joint'>0 0 0 0 -0 0</pose>
        <inertial>
          <pose>-0.3323 0 0.068 0 -0 0</pose>
          <mass>4.27</mass>
          <inertia>
            <ixx>0.01014</ixx>
            <ixy>8e-05</ixy>
            <ixz>0.00916</ixz>
            <iyy>0.30928</iyy>
            <iyz>0</iyz>
            <izz>0.30646</izz>
          </inertia>
        </inertial>
        <collision name='forearm_link_collision'>
          <pose>0 0 0.049042 1.5708 0 -1.5708</pose>
          <geometry>
            <mesh>
              <scale>1 1 1</scale>
              <uri>file:///home/farhan/ros2_ws/install/ur_description/share/ur_description/meshes/ur10/collision/forearm.stl</uri>
            </mesh>
          </geometry>
          <max_contacts>10</max_contacts>
          <surface>
            <contact>
              <ode/>
            </contact>
            <bounce/>
            <friction>
              <torsional>
                <ode/>
              </torsional>
              <ode/>
            </friction>
          </surface>
        </collision>
        <visual name='forearm_link_visual'>
          <pose>0 0 0.049042 1.5708 0 -1.5708</pose>
          <geometry>
            <mesh>
              <scale>1 1 1</scale>
              <uri>file:///home/farhan/ros2_ws/install/ur_description/share/ur_description/meshes/ur10/visual/forearm.dae</uri>
            </mesh>
          </geometry>
        </visual>
        <self_collide>0</self_collide>
        <enable_wind>0</enable_wind>
        <kinematic>0</kinematic>
      </link>
      <joint name='wrist_1_joint' type='revolute'>
        <pose relative_to='forearm_link'>-0.5723 0 0.163941 0 -0 0</pose>
        <parent>forearm_link</parent>
        <child>wrist_1_link</child>
        <axis>
          <xyz>0 0 1</xyz>
          <limit>
            <lower>-6.28319</lower>
            <upper>6.28319</upper>
            <effort>56</effort>
            <velocity>3.14159</velocity>
          </limit>
          <dynamics>
            <damping>0</damping>
            <friction>0</friction>
            <spring_reference>0</spring_reference>
            <spring_stiffness>0</spring_stiffness>
          </dynamics>
        </axis>
      </joint>
      <link name='wrist_1_link'>
        <pose relative_to='wrist_1_joint'>0 0 0 0 -0 0</pose>
        <inertial>
          <pose>0 -0.018 0.007 1.5708 -0 0</pose>
          <mass>2</mass>
          <inertia>
            <ixx>0.00296</ixx>
            <ixy>-1e-05</ixy>
            <ixz>0</ixz>
            <iyy>0.00222</iyy>
            <iyz>-0.00024</iyz>
            <izz>0.00258</izz>
          </inertia>
        </inertial>
        <collision name='wrist_1_link_collision'>
          <pose>0 0 -0.1149 1.5708 -0 0</pose>
          <geometry>
            <mesh>
              <scale>1 1 1</scale>
              <uri>file:///home/farhan/ros2_ws/install/ur_description/share/ur_description/meshes/ur10/collision/wrist1.stl</uri>
            </mesh>
          </geometry>
          <max_contacts>10</max_contacts>
          <surface>
            <contact>
              <ode/>
            </contact>
            <bounce/>
            <friction>
              <torsional>
                <ode/>
              </torsional>
              <ode/>
            </friction>
          </surface>
        </collision>
        <visual name='wrist_1_link_visual'>
          <pose>0 0 -0.1149 1.5708 -0 0</pose>
          <geometry>
            <mesh>
              <scale>1 1 1</scale>
              <uri>file:///home/farhan/ros2_ws/install/ur_description/share/ur_description/meshes/ur10/visual/wrist1.dae</uri>
            </mesh>
          </geometry>
        </visual>
        <self_collide>0</self_collide>
        <enable_wind>0</enable_wind>
        <kinematic>0</kinematic>
      </link>
      <joint name='wrist_2_joint' type='revolute'>
        <pose relative_to='wrist_1_link'>0 -0.1157 -0 1.5708 -0 0</pose>
        <parent>wrist_1_link</parent>
        <child>wrist_2_link</child>
        <axis>
          <xyz>0 0 1</xyz>
          <limit>
            <lower>-6.28319</lower>
            <upper>6.28319</upper>
            <effort>56</effort>
            <velocity>3.14159</velocity>
          </limit>
          <dynamics>
            <damping>0</damping>
            <friction>0</friction>
            <spring_reference>0</spring_reference>
            <spring_stiffness>0</spring_stiffness>
          </dynamics>
        </axis>
      </joint>
      <link name='wrist_2_link'>
        <pose relative_to='wrist_2_joint'>0 0 0 0 -0 0</pose>
        <inertial>
          <pose>0 0.018 -0.007 -1.5708 0 0</pose>
          <mass>2</mass>
          <inertia>
            <ixx>0.00296</ixx>
            <ixy>-1e-05</ixy>
            <ixz>0</ixz>
            <iyy>0.00222</iyy>
            <iyz>-0.00024</iyz>
            <izz>0.00258</izz>
          </inertia>
        </inertial>
        <collision name='wrist_2_link_collision'>
          <pose>0 0 -0.1158 0 -0 0</pose>
          <geometry>
            <mesh>
              <scale>1 1 1</scale>
              <uri>file:///home/farhan/ros2_ws/install/ur_description/share/ur_description/meshes/ur10/collision/wrist2.stl</uri>
            </mesh>
          </geometry>
          <max_contacts>10</max_contacts>
          <surface>
            <contact>
              <ode/>
            </contact>
            <bounce/>
            <friction>
              <torsional>
                <ode/>
              </torsional>
              <ode/>
            </friction>
          </surface>
        </collision>
        <visual name='wrist_2_link_visual'>
          <pose>0 0 -0.1158 0 -0 0</pose>
          <geometry>
            <mesh>
              <scale>1 1 1</scale>
              <uri>file:///home/farhan/ros2_ws/install/ur_description/share/ur_description/meshes/ur10/visual/wrist2.dae</uri>
            </mesh>
          </geometry>
        </visual>
        <self_collide>0</self_collide>
        <enable_wind>0</enable_wind>
        <kinematic>0</kinematic>
      </link>
      <joint name='wrist_3_joint' type='revolute'>
        <pose relative_to='wrist_2_link'>0 0.0922 -0 -1.5708 0 0</pose>
        <parent>wrist_2_link</parent>
        <child>wrist_3_link</child>
        <axis>
          <xyz>0 0 1</xyz>
          <limit>
            <lower>-6.28319</lower>
            <upper>6.28319</upper>
            <effort>56</effort>
            <velocity>3.14159</velocity>
          </limit>
          <dynamics>
            <damping>0</damping>
            <friction>0</friction>
            <spring_reference>0</spring_reference>
            <spring_stiffness>0</spring_stiffness>
          </dynamics>
        </axis>
      </joint>
      <link name='wrist_3_link'>
        <pose relative_to='wrist_3_joint'>0 0 0 0 -0 0</pose>
        <inertial>
          <pose>6e-06 -0.010188 0.006135 0 -0 0</pose>
          <mass>1.2479</mass>
          <inertia>
            <ixx>0.0025007</ixx>
            <ixy>3.64639e-07</ixy>
            <ixz>1.78391e-07</ixz>
            <iyy>0.00197875</iyy>
            <iyz>-0.000327433</iyz>
            <izz>0.0013469</izz>
          </inertia>
        </inertial>
        <collision name='wrist_3_link_collision'>
          <pose>0 0 -0.0922 1.5708 -0 0</pose>
          <geometry>
            <mesh>
              <scale>1 1 1</scale>
              <uri>file:///home/farhan/ros2_ws/install/ur_description/share/ur_description/meshes/ur10/collision/wrist3.stl</uri>
            </mesh>
          </geometry>
          <max_contacts>10</max_contacts>
          <surface>
            <contact>
              <ode/>
            </contact>
            <bounce/>
            <friction>
              <torsional>
                <ode/>
              </torsional>
              <ode/>
            </friction>
          </surface>
        </collision>
        <collision name='wrist_3_link_fixed_joint_lump__camera_link_collision_1'>
          <pose>0 -0.06 -0.01 0 -1.5 1.57</pose>
          <geometry>
            <mesh>
              <scale>1 1 1</scale>
              <uri>model://ur10_robotiq/meshes/sensors/camera/kinetic.dae</uri>
            </mesh>
          </geometry>
          <surface>
            <contact>
              <ode/>
            </contact>
            <friction>
              <ode/>
              <torsional>
                <ode/>
              </torsional>
            </friction>
            <bounce/>
          </surface>
          <max_contacts>10</max_contacts>
        </collision>
        <collision name='wrist_3_link_fixed_joint_lump__robotiq_85_base_link_collision_2'>
          <pose>0 0 0 0 -0 0</pose>
          <geometry>
            <mesh>
              <scale>1 1 1</scale>
              <uri>model://robotiq_description/meshes/collision/2f_85/robotiq_base.stl</uri>
            </mesh>
          </geometry>
          <max_contacts>10</max_contacts>
          <surface>
            <contact>
              <ode/>
            </contact>
            <bounce/>
            <friction>
              <torsional>
                <ode/>
              </torsional>
              <ode/>
            </friction>
          </surface>
        </collision>
        <visual name='wrist_3_link_visual'>
          <pose>0 0 -0.0922 1.5708 -0 0</pose>
          <geometry>
            <mesh>
              <scale>1 1 1</scale>
              <uri>file:///home/farhan/ros2_ws/install/ur_description/share/ur_description/meshes/ur10/visual/wrist3.dae</uri>
            </mesh>
          </geometry>
        </visual>
        <visual name='wrist_3_link_fixed_joint_lump__camera_link_visual_1'>
          <pose>0 -0.06 -0.01 0 -1.5 1.57</pose>
          <geometry>
            <mesh>
              <scale>1 1 1</scale>
              <uri>model://ur10_robotiq/meshes/sensors/camera/kinetic.stl</uri>
            </mesh>
          </geometry>
        </visual>
        <visual name='wrist_3_link_fixed_joint_lump__robotiq_85_base_link_visual_2'>
          <pose>0 0 0 0 -0 0</pose>
          <geometry>
            <mesh>
              <scale>1 1 1</scale>
              <uri>model://robotiq_description/meshes/visual/2f_85/robotiq_base.dae</uri>
            </mesh>
          </geometry>
        </visual>
        <sensor name='camera' type='depth'>
          <visualize>1</visualize>
          <update_rate>10</update_rate>
          <camera>
            <horizontal_fov>1.089</horizontal_fov>
            <image>
              <format>R8G8B8</format>
              <width>640</width>
              <height>480</height>
            </image>
            <clip>
              <near>0.05</near>
              <far>8</far>
            </clip>
          </camera>
          <plugin name='camera_controller' filename='libgazebo_ros_camera.so'>
            <frame_name>camera_optical_link</frame_name>
          </plugin>
          <pose>0 -0.06 -0.01 0 -1.5 1.57</pose>
        </sensor>
        <self_collide>0</self_collide>
        <enable_wind>0</enable_wind>
        <kinematic>0</kinematic>
      </link>
      <joint name='robotiq_85_left_inner_knuckle_joint' type='revolute'>
        <pose relative_to='wrist_3_link'>0.0127 0 0.06142 0 -0 0</pose>
        <parent>wrist_3_link</parent>
        <child>robotiq_85_left_inner_knuckle_link</child>
        <axis>
          <xyz>0 -1 0</xyz>
          <limit>
            <lower>-1e+16</lower>
            <upper>1e+16</upper>
          </limit>
          <dynamics>
            <spring_reference>0</spring_reference>
            <spring_stiffness>0</spring_stiffness>
          </dynamics>
        </axis>
      </joint>
      <link name='robotiq_85_left_inner_knuckle_link'>
        <pose relative_to='robotiq_85_left_inner_knuckle_joint'>0 0 0 0 -0 0</pose>
        <inertial>
          <pose>0.018977 0.00015 0.022471 0 -0 0</pose>
          <mass>0.0296938</mass>
          <inertia>
            <ixx>9.57136e-06</ixx>
            <ixy>0</ixy>
            <ixz>-3.93424e-06</ixz>
            <iyy>8.69056e-06</iyy>
            <iyz>0</iyz>
            <izz>8.19144e-06</izz>
          </inertia>
        </inertial>
        <collision name='robotiq_85_left_inner_knuckle_link_collision'>
          <pose>0 0 0 0 -0 0</pose>
          <geometry>
            <mesh>
              <scale>1 1 1</scale>
              <uri>model://robotiq_description/meshes/collision/2f_85/left_inner_knuckle.stl</uri>
            </mesh>
          </geometry>
          <max_contacts>10</max_contacts>
          <surface>
            <contact>
              <ode/>
            </contact>
            <bounce/>
            <friction>
              <torsional>
                <ode/>
              </torsional>
              <ode/>
            </friction>
          </surface>
        </collision>
        <visual name='robotiq_85_left_inner_knuckle_link_visual'>
          <pose>0 0 0 0 -0 0</pose>
          <geometry>
            <mesh>
              <scale>1 1 1</scale>
              <uri>model://robotiq_description/meshes/visual/2f_85/left_inner_knuckle.dae</uri>
            </mesh>
          </geometry>
        </visual>
        <self_collide>0</self_collide>
        <enable_wind>0</enable_wind>
        <kinematic>0</kinematic>
      </link>
      <joint name='robotiq_85_left_knuckle_joint' type='revolute'>
        <pose relative_to='wrist_3_link'>0.030601 0 0.054905 0 -0 0</pose>
        <parent>wrist_3_link</parent>
        <child>robotiq_85_left_knuckle_link</child>
        <axis>
          <xyz>0 -1 0</xyz>
          <limit>
            <lower>0</lower>
            <upper>0.8</upper>
            <effort>50</effort>
            <velocity>0.5</velocity>
          </limit>
          <dynamics>
            <spring_reference>0</spring_reference>
            <spring_stiffness>0</spring_stiffness>
          </dynamics>
        </axis>
      </joint>
      <link name='robotiq_85_left_knuckle_link'>
        <pose relative_to='robotiq_85_left_knuckle_joint'>0 0 0 0 -0 0</pose>
        <inertial>
          <pose>0.029387 -0.000551 0.011107 0 -0 0</pose>
          <mass>0.0564515</mass>
          <inertia>
            <ixx>1.67295e-05</ixx>
            <ixy>2.37618e-07</ixy>
            <ixz>-5.75738e-06</ixz>
            <iyy>2.21234e-05</iyy>
            <iyz>1.61032e-07</iyz>
            <izz>1.29013e-05</izz>
          </inertia>
        </inertial>
        <collision name='robotiq_85_left_knuckle_link_collision'>
          <pose>0 0 0 0 -0 0</pose>
          <geometry>
            <mesh>
              <scale>1 1 1</scale>
              <uri>model://robotiq_description/meshes/collision/2f_85/left_knuckle.stl</uri>
            </mesh>
          </geometry>
          <max_contacts>10</max_contacts>
          <surface>
            <contact>
              <ode/>
            </contact>
            <bounce/>
            <friction>
              <torsional>
                <ode/>
              </torsional>
              <ode/>
            </friction>
          </surface>
        </collision>
        <collision name='robotiq_85_left_knuckle_link_fixed_joint_lump__robotiq_85_left_finger_link_collision_1'>
          <pose>0.031526 0 -0.003763 0 -0 0</pose>
          <geometry>
            <mesh>
              <scale>1 1 1</scale>
              <uri>model://robotiq_description/meshes/collision/2f_85/left_finger.stl</uri>
            </mesh>
          </geometry>
          <max_contacts>10</max_contacts>
          <surface>
            <contact>
              <ode/>
            </contact>
            <bounce/>
            <friction>
              <torsional>
                <ode/>
              </torsional>
              <ode/>
            </friction>
          </surface>
        </collision>
        <visual name='robotiq_85_left_knuckle_link_visual'>
          <pose>0 0 0 0 -0 0</pose>
          <geometry>
            <mesh>
              <scale>1 1 1</scale>
              <uri>model://robotiq_description/meshes/visual/2f_85/left_knuckle.dae</uri>
            </mesh>
          </geometry>
        </visual>
        <visual name='robotiq_85_left_knuckle_link_fixed_joint_lump__robotiq_85_left_finger_link_visual_1'>
          <pose>0.031526 0 -0.003763 0 -0 0</pose>
          <geometry>
            <mesh>
              <scale>1 1 1</scale>
              <uri>model://robotiq_description/meshes/visual/2f_85/left_finger.dae</uri>
            </mesh>
          </geometry>
        </visual>
        <self_collide>0</self_collide>
        <enable_wind>0</enable_wind>
        <kinematic>0</kinematic>
      </link>
      <joint name='robotiq_85_left_finger_tip_joint' type='revolute'>
        <pose relative_to='robotiq_85_left_knuckle_link'>0.037158 0 0.043422 0 -0 0</pose>
        <parent>robotiq_85_left_knuckle_link</parent>
        <child>robotiq_85_left_finger_tip_link</child>
        <axis>
          <xyz>0 -1 0</xyz>
          <limit>
            <lower>-1e+16</lower>
            <upper>1e+16</upper>
          </limit>
          <dynamics>
            <spring_reference>0</spring_reference>
            <spring_stiffness>0</spring_stiffness>
          </dynamics>
        </axis>
      </joint>
      <link name='robotiq_85_left_finger_tip_link'>
        <pose relative_to='robotiq_85_left_finger_tip_joint'>0 0 0 0 -0 0</pose>
        <inertial>
          <pose>-0.014567 -0.0008 0.016497 0 -0 0</pose>
          <mass>0.0426859</mass>
          <inertia>
            <ixx>1.04815e-05</ixx>
            <ixy>0</ixy>
            <ixz>3.5232e-06</ixz>
            <iyy>1.19789e-05</iyy>
            <iyz>0</iyz>
            <izz>4.22784e-06</izz>
          </inertia>
        </inertial>
        <collision name='robotiq_85_left_finger_tip_link_collision'>
          <pose>0 0 0 0 -0 0</pose>
          <geometry>
            <mesh>
              <scale>1 1 1</scale>
              <uri>model://robotiq_description/meshes/collision/2f_85/left_finger_tip.stl</uri>
            </mesh>
          </geometry>
          <max_contacts>10</max_contacts>
          <surface>
            <contact>
              <ode/>
            </contact>
            <bounce/>
            <friction>
              <torsional>
                <ode/>
              </torsional>
              <ode/>
            </friction>
          </surface>
        </collision>
        <visual name='robotiq_85_left_finger_tip_link_visual'>
          <pose>0 0 0 0 -0 0</pose>
          <geometry>
            <mesh>
              <scale>1 1 1</scale>
              <uri>model://robotiq_description/meshes/visual/2f_85/left_finger_tip.dae</uri>
            </mesh>
          </geometry>
        </visual>
        <self_collide>0</self_collide>
        <enable_wind>0</enable_wind>
        <kinematic>0</kinematic>
      </link>
      <joint name='robotiq_85_right_inner_knuckle_joint' type='revolute'>
        <pose relative_to='wrist_3_link'>-0.0127 -0 0.06142 0 -0 0</pose>
        <parent>wrist_3_link</parent>
        <child>robotiq_85_right_inner_knuckle_link</child>
        <axis>
          <xyz>0 -1 0</xyz>
          <limit>
            <lower>-1e+16</lower>
            <upper>1e+16</upper>
          </limit>
          <dynamics>
            <spring_reference>0</spring_reference>
            <spring_stiffness>0</spring_stiffness>
          </dynamics>
        </axis>
      </joint>
      <link name='robotiq_85_right_inner_knuckle_link'>
        <pose relative_to='robotiq_85_right_inner_knuckle_joint'>0 0 0 0 -0 0</pose>
        <inertial>
          <pose>-0.019268 5e-05 0.022222 0 -0 0</pose>
          <mass>0.0296938</mass>
          <inertia>
            <ixx>9.42456e-06</ixx>
            <ixy>0</ixy>
            <ixz>3.9636e-06</ixz>
            <iyy>8.69056e-06</iyy>
            <iyz>0</iyz>
            <izz>8.33824e-06</izz>
          </inertia>
        </inertial>
        <collision name='robotiq_85_right_inner_knuckle_link_collision'>
          <pose>0 0 0 0 -0 0</pose>
          <geometry>
            <mesh>
              <scale>1 1 1</scale>
              <uri>model://robotiq_description/meshes/collision/2f_85/right_inner_knuckle.stl</uri>
            </mesh>
          </geometry>
          <max_contacts>10</max_contacts>
          <surface>
            <contact>
              <ode/>
            </contact>
            <bounce/>
            <friction>
              <torsional>
                <ode/>
              </torsional>
              <ode/>
            </friction>
          </surface>
        </collision>
        <visual name='robotiq_85_right_inner_knuckle_link_visual'>
          <pose>0 0 0 0 -0 0</pose>
          <geometry>
            <mesh>
              <scale>1 1 1</scale>
              <uri>model://robotiq_description/meshes/visual/2f_85/right_inner_knuckle.dae</uri>
            </mesh>
          </geometry>
        </visual>
        <self_collide>0</self_collide>
        <enable_wind>0</enable_wind>
        <kinematic>0</kinematic>
      </link>
      <joint name='robotiq_85_right_knuckle_joint' type='revolute'>
        <pose relative_to='wrist_3_link'>-0.030601 0 0.054905 0 -0 0</pose>
        <parent>wrist_3_link</parent>
        <child>robotiq_85_right_knuckle_link</child>
        <axis>
          <xyz>0 -1 0</xyz>
          <limit>
            <lower>-0.8</lower>
            <upper>0</upper>
            <effort>50</effort>
            <velocity>0.5</velocity>
          </limit>
          <dynamics>
            <spring_reference>0</spring_reference>
            <spring_stiffness>0</spring_stiffness>
          </dynamics>
        </axis>
      </joint>
      <link name='robotiq_85_right_knuckle_link'>
        <pose relative_to='robotiq_85_right_knuckle_joint'>0 0 0 0 -0 0</pose>
        <inertial>
          <pose>-0.029387 4.5e-05 0.011107 0 -0 0</pose>
          <mass>0.0564515</mass>
          <inertia>
            <ixx>1.67196e-05</ixx>
            <ixy>-4.91092e-08</ixy>
            <ixz>5.75738e-06</ixz>
            <iyy>2.21234e-05</iyy>
            <iyz>3.3281e-08</iyz>
            <izz>1.28914e-05</izz>
          </inertia>
        </inertial>
        <collision name='robotiq_85_right_knuckle_link_collision'>
          <pose>0 0 0 0 -0 0</pose>
          <geometry>
            <mesh>
              <scale>1 1 1</scale>
              <uri>model://robotiq_description/meshes/collision/2f_85/right_knuckle.stl</uri>
            </mesh>
          </geometry>
          <max_contacts>10</max_contacts>
          <surface>
            <contact>
              <ode/>
            </contact>
            <bounce/>
            <friction>
              <torsional>
                <ode/>
              </torsional>
              <ode/>
            </friction>
          </surface>
        </collision>
        <collision name='robotiq_85_right_knuckle_link_fixed_joint_lump__robotiq_85_right_finger_link_collision_1'>
          <pose>-0.031526 0 -0.003763 0 -0 0</pose>
          <geometry>
            <mesh>
              <scale>1 1 1</scale>
              <uri>model://robotiq_description/meshes/collision/2f_85/right_finger.stl</uri>
            </mesh>
          </geometry>
          <max_contacts>10</max_contacts>
          <surface>
            <contact>
              <ode/>
            </contact>
            <bounce/>
            <friction>
              <torsional>
                <ode/>
              </torsional>
              <ode/>
            </friction>
          </surface>
        </collision>
        <visual name='robotiq_85_right_knuckle_link_visual'>
          <pose>0 0 0 0 -0 0</pose>
          <geometry>
            <mesh>
              <scale>1 1 1</scale>
              <uri>model://robotiq_description/meshes/visual/2f_85/right_knuckle.dae</uri>
            </mesh>
          </geometry>
        </visual>
        <visual name='robotiq_85_right_knuckle_link_fixed_joint_lump__robotiq_85_right_finger_link_visual_1'>
          <pose>-0.031526 0 -0.003763 0 -0 0</pose>
          <geometry>
            <mesh>
              <scale>1 1 1</scale>
              <uri>model://robotiq_description/meshes/visual/2f_85/right_finger.dae</uri>
            </mesh>
          </geometry>
        </visual>
        <self_collide>0</self_collide>
        <enable_wind>0</enable_wind>
        <kinematic>0</kinematic>
      </link>
      <joint name='robotiq_85_right_finger_tip_joint' type='revolute'>
        <pose relative_to='robotiq_85_right_knuckle_link'>-0.037158 0 0.043422 0 -0 0</pose>
        <parent>robotiq_85_right_knuckle_link</parent>
        <child>robotiq_85_right_finger_tip_link</child>
        <axis>
          <xyz>0 -1 0</xyz>
          <limit>
            <lower>-1e+16</lower>
            <upper>1e+16</upper>
          </limit>
          <dynamics>
            <spring_reference>0</spring_reference>
            <spring_stiffness>0</spring_stiffness>
          </dynamics>
        </axis>
      </joint>
      <link name='robotiq_85_right_finger_tip_link'>
        <pose relative_to='robotiq_85_right_finger_tip_joint'>0 0 0 0 -0 0</pose>
        <inertial>
          <pose>0.014567 5e-05 0.016497 0 -0 0</pose>
          <mass>0.0426859</mass>
          <inertia>
            <ixx>1.04815e-05</ixx>
            <ixy>0</ixy>
            <ixz>-3.5232e-06</ixz>
            <iyy>1.19789e-05</iyy>
            <iyz>0</iyz>
            <izz>4.22784e-06</izz>
          </inertia>
        </inertial>
        <collision name='robotiq_85_right_finger_tip_link_collision'>
          <pose>0 0 0 0 -0 0</pose>
          <geometry>
            <mesh>
              <scale>1 1 1</scale>
              <uri>model://robotiq_description/meshes/collision/2f_85/right_finger_tip.stl</uri>
            </mesh>
          </geometry>
          <max_contacts>10</max_contacts>
          <surface>
            <contact>
              <ode/>
            </contact>
            <bounce/>
            <friction>
              <torsional>
                <ode/>
              </torsional>
              <ode/>
            </friction>
          </surface>
        </collision>
        <visual name='robotiq_85_right_finger_tip_link_visual'>
          <pose>0 0 0 0 -0 0</pose>
          <geometry>
            <mesh>
              <scale>1 1 1</scale>
              <uri>model://robotiq_description/meshes/visual/2f_85/right_finger_tip.dae</uri>
            </mesh>
          </geometry>
        </visual>
        <self_collide>0</self_collide>
        <enable_wind>0</enable_wind>
        <kinematic>0</kinematic>
      </link>
      <static>0</static>
      <plugin name='gazebo_ros2_control' filename='libgazebo_ros2_control.so'>
        <parameters>/home/farhan/ros2_ws/install/ur10_robotiq/share/ur10_robotiq/config/ur10_controllers_gripper.yaml</parameters>
      </plugin>
      <pose>0 0 0.965 0 -0 0</pose>
    </model>
    <model name='coca_cola'>
      <link name='link'>
        <pose>0 0 0.115 0 -0 0</pose>
        <inertial>
          <mass>0.39</mass>
          <inertia>
            <ixx>0.00058</ixx>
            <ixy>0</ixy>
            <ixz>0</ixz>
            <iyy>0.00058</iyy>
            <iyz>0</iyz>
            <izz>0.00019</izz>
          </inertia>
          <pose>0 0 0 0 -0 0</pose>
        </inertial>
        <collision name='collision'>
          <geometry>
            <cylinder>
              <radius>0.0301625</radius>
              <length>0.12065</length>
            </cylinder>
          </geometry>
          <max_contacts>10</max_contacts>
          <surface>
            <contact>
              <ode/>
            </contact>
            <bounce/>
            <friction>
              <torsional>
                <ode/>
              </torsional>
              <ode/>
            </friction>
          </surface>
        </collision>
        <visual name='bodyMesh'>
          <geometry>
            <mesh>
              <uri>model://coca_cola/meshes/coke.dae</uri>
              <scale>1 1 1</scale>
            </mesh>
          </geometry>
        </visual>
        <self_collide>0</self_collide>
        <enable_wind>0</enable_wind>
        <kinematic>0</kinematic>
      </link>
      <pose>0.113182 -1.02254 0 0 -0 0</pose>
    </model>
  </world>
</sdf>
